<?xml version="1.0" ?>
<!-- =================================================================================== -->
<!-- |    This document was autogenerated by xacro from robot.urdf.xacro               | -->
<!-- |    EDITING THIS FILE BY HAND IS NOT RECOMMENDED                                 | -->
<!-- =================================================================================== -->
<robot name="dhtbot_one">
  <!-- Specify some standard inertial calculations https://en.wikipedia.org/wiki/List_of_moments_of_inertia -->
  <!-- These make use of xacro's mathematical functionality -->
  <material name="white">
    <color rgba="1 1 1 1"/>
  </material>
  <material name="orange">
    <color rgba="1 0.3 0.1 1"/>
  </material>
  <material name="gray">
    <color rgba="0.7 0.7 0.7 1"/>
  </material>
  <material name="black">
    <color rgba="0 0 0 1"/>
  </material>
  <material name="red">
    <color rgba="1 0 0 1"/>
  </material>
  <!-- BASE LINK -->
  <link name="base_link">
    
    </link>
  <!-- CHASSIS LINK -->
  <joint name="chassis_joint" type="fixed">
    <parent link="base_link"/>
    <child link="chassis"/>
    <origin xyz="0 0 0"/>
  </joint>
  <link name="chassis">
    <visual>
      <origin xyz="0 0 -0.015"/>
      <!--<origin xyz="0 0 0.045"/>-->
      <geometry>
        <mesh filename="file:////home/isi/ros2_ws/install/dhtbot_one/share/dhtbot_one/meshes/base_link.STL" scale="1 1 1"/>
        --&gt;
                
        <!--<cylinder radius="0.115" length="0.12"/>-->
      </geometry>
      <material name="white"/>
    </visual>
    <collision>
      <origin xyz="0 0 0.045"/>
      <geometry>
        <cylinder length="0.12" radius="0.115"/>
      </geometry>
    </collision>
    <inertial>
      <origin rpy="0 0 0" xyz="0.03 0 0"/>
      <mass value="1.0"/>
      <inertia ixx="0.00450625" ixy="0.0" ixz="0.0" iyy="0.00450625" iyz="0.0" izz="0.0066125"/>
    </inertial>
  </link>
  <gazebo reference="chassis">
    <material>Gazebo/White</material>
  </gazebo>
  <!-- LEFT WHEEL LINK -->
  <joint name="left_wheel_joint" type="continuous">
    <parent link="base_link"/>
    <child link="left_wheel"/>
    <origin rpy="-1.5707963267948966 0 0" xyz="0 0.0875 0"/>
    <axis xyz="0 0 1"/>
  </joint>
  <link name="left_wheel">
    <visual>
      <geometry>
        <cylinder length="0.025" radius="0.0325"/>
      </geometry>
      <material name="black"/>
    </visual>
    <collision>
      <geometry>
        <cylinder length="0.025" radius="0.0325"/>
      </geometry>
    </collision>
    <inertial>
      <origin rpy="0 0 0" xyz="0 0 0"/>
      <mass value="0.1"/>
      <inertia ixx="3.161458333333334e-05" ixy="0.0" ixz="0.0" iyy="3.161458333333334e-05" iyz="0.0" izz="5.281250000000001e-05"/>
    </inertial>
  </link>
  <gazebo reference="left_wheel">
    <material>Gazebo/Black</material>
    <mu1 value="1.0"/>
    <mu2 value="1.0"/>
  </gazebo>
  <!-- RIGHT WHEEL LINK -->
  <joint name="right_wheel_joint" type="continuous">
    <parent link="base_link"/>
    <child link="right_wheel"/>
    <origin rpy="1.5707963267948966 0 0" xyz="0 -0.0875 0"/>
    <axis xyz="0 0 -1"/>
  </joint>
  <link name="right_wheel">
    <visual>
      <geometry>
        <cylinder length="0.025" radius="0.0325"/>
      </geometry>
      <material name="black"/>
    </visual>
    <collision>
      <geometry>
        <cylinder length="0.025" radius="0.0325"/>
      </geometry>
    </collision>
    <inertial>
      <origin rpy="0 0 0" xyz="0 0 0"/>
      <mass value="0.1"/>
      <inertia ixx="3.161458333333334e-05" ixy="0.0" ixz="0.0" iyy="3.161458333333334e-05" iyz="0.0" izz="5.281250000000001e-05"/>
    </inertial>
  </link>
  <gazebo reference="right_wheel">
    <material>Gazebo/Black</material>
    <mu1 value="1.0"/>
    <mu2 value="1.0"/>
  </gazebo>
  <!-- CASTER WHEEL LINK -->
  <joint name="caster_wheel_joint" type="fixed">
    <parent link="chassis"/>
    <child link="caster_wheel"/>
    <origin xyz="0.09 0 -0.015"/>
  </joint>
  <link name="caster_wheel">
    <visual>
      <geometry>
        <mesh filename="file:////home/isi/ros2_ws/install/dhtbot_one/share/dhtbot_one/meshes/caster_wheel_link.STL"/>
        -
            
      </geometry>
      <material name="white"/>
    </visual>
    <collision>
      <geometry>
        <sphere radius="0.0175"/>
      </geometry>
    </collision>
    <inertial>
      <origin rpy="0 0 0" xyz="0 0 0"/>
      <mass value="0.05"/>
      <inertia ixx="6.125000000000002e-06" ixy="0.0" ixz="0.0" iyy="6.125000000000002e-06" iyz="0.0" izz="6.125000000000002e-06"/>
    </inertial>
  </link>
  <gazebo reference="caster_wheel">
    <material>Gazebo/Black</material>
    <mu1 value="0.001"/>
    <mu2 value="0.001"/>
  </gazebo>
  <joint name="laser_joint" type="fixed">
    <parent link="chassis"/>
    <child link="laser_frame"/>
    <origin rpy="0 0 0" xyz="0 0 0.13"/>
  </joint>
  <link name="laser_frame">
    <visual>
      <origin rpy="0 0 3.141592653589793" xyz="0 0 0"/>
      <geometry>
        <mesh filename="file:////home/isi/ros2_ws/install/dhtbot_one/share/dhtbot_one/meshes/lds.stl" scale="0.001 0.001 0.001"/>
      </geometry>
      <material name="gray"/>
    </visual>
    <collision>
      <origin xyz="0 0 -0.015"/>
      <geometry>
        <cylinder length="0.06" radius="0.04"/>
      </geometry>
    </collision>
    <inertial>
      <origin rpy="0 0 0" xyz="0 0 0"/>
      <mass value="0.1"/>
      <inertia ixx="7e-05" ixy="0.0" ixz="0.0" iyy="7e-05" iyz="0.0" izz="8e-05"/>
    </inertial>
  </link>
  <gazebo reference="laser_frame">
    <material>Gazebo/Gray</material>
    <sensor name="laser" type="ray">
      <pose> 0 0 0 0 0 0 </pose>
      <visualize>false</visualize>
      <update_rate>10</update_rate>
      <ray>
        <scan>
          <horizontal>
            <samples>3600</samples>
            <min_angle>-3.1415</min_angle>
            <max_angle>3.1415</max_angle>
          </horizontal>
        </scan>
        <range>
          <min>0.2</min>
          <max>12</max>
        </range>
        <noise>
          <type>gaussian</type>
          <mean>0</mean>
          <stddev>0.01</stddev>
        </noise>
      </ray>
      <plugin filename="libgazebo_ros_ray_sensor.so" name="laser_controller">
        <ros>
          <argument>~/out:=scan</argument>
        </ros>
        <output_type>sensor_msgs/LaserScan</output_type>
        <frame_name>laser_frame</frame_name>
      </plugin>
    </sensor>
  </gazebo>
  <!-- CAMERA LINK -->
  <joint name="camera_joint" type="fixed">
    <parent link="chassis"/>
    <child link="camera_link"/>
    <origin xyz="0.09 0 0.11"/>
  </joint>
  <link name="camera_link">
    <visual>
      <origin xyz="0 0 0"/>
      <geometry>
        <box size="0.02 0.025 0.025"/>
      </geometry>
      <material name="orange"/>
    </visual>
    <visual>
      <origin rpy="0 1.5707963267948966 0" xyz="0.015 0 0"/>
      <geometry>
        <cylinder length="0.01" radius="0.0075"/>
      </geometry>
      <material name="orange"/>
    </visual>
    <collision>
      <origin xyz="0.01 0 0"/>
      <geometry>
        <box size="0.03 0.025 0.025"/>
      </geometry>
    </collision>
    <inertial>
      <origin rpy="0 0 0" xyz="0 0 0"/>
      <mass value="0.05"/>
      <inertia ixx="5.208333333333334e-06" ixy="0.0" ixz="0.0" iyy="6.354166666666667e-06" iyz="0.0" izz="6.354166666666667e-06"/>
    </inertial>
  </link>
  <joint name="camera_optical_joint" type="fixed">
    <origin rpy="-1.5707963267948966 0 -1.5707963267948966" xyz="0 0 0"/>
    <parent link="camera_link"/>
    <child link="camera_link_optical"/>
  </joint>
  <link name="camera_link_optical"/>
  <!-- GAZEBO CAMERA PLUGIN -->
  <gazebo reference="camera_link">
    <material>Gazebo/Orange</material>
    <sensor name="camera" type="camera">
      <pose> 0 0 0 0 0 0 </pose>
      <visualize>true</visualize>
      <update_rate>30</update_rate>
      <camera>
        <horizontal_fov>1.3962634</horizontal_fov>
        <image>
          <format>R8G8B8</format>
          <width>640</width>
          <height>480</height>
        </image>
        <clip>
          <near>0.05</near>
          <far>18.0</far>
        </clip>
      </camera>
      <plugin filename="libgazebo_ros_camera.so" name="camera_controller">
        <frame_name>camera_link_optical</frame_name>
      </plugin>
    </sensor>
  </gazebo>
  <hardware>
    <!-- Plugin hardware cho Gazebo Sim (gz_ros2_control) -->
    <plugin>gz_ros2_control/GazeboSimSystem</plugin>
  </hardware>
  <!-- ĐÚNG tên joint bánh xe -->
  <joint name="left_wheel_joint">
    <command_interface name="velocity">
      <param name="min">-5.0</param>
      <param name="max">5.0</param>
    </command_interface>
    <state_interface name="position"/>
    <state_interface name="velocity"/>
  </joint>
  <joint name="right_wheel_joint">
    <command_interface name="velocity">
      <param name="min">-5.0</param>
      <param name="max">5.0</param>
    </command_interface>
    <state_interface name="position"/>
    <state_interface name="velocity"/>
  </joint>
  <plugin filename="gz_ros2_control-system" name="gz_ros2_control::GazeboSimROS2ControlPlugin">
    <!-- file YAML khai báo diff_cont + joint_broad -->
    <parameters>/home/isi/ros2_ws/install/dhtbot_one/share/dhtbot_one/config/my_controllers.yaml</parameters>
    <!-- Tên node controller_manager trong ROS graph -->
    <controller_manager_name>controller_manager</controller_manager_name>
    <!-- Đọc URDF từ tham số robot_description của robot_state_publisher -->
    <robot_param>robot_description</robot_param>
    <robot_param_node>robot_state_publisher</robot_param_node>
  </plugin>
</robot>
